File: data/Horiba_MacroRAM/acetonitrile.txt
#Acq. time (s)=	10
#Accumulations=	5
#AutoExposure=	Off
#Spike filter=	Multiple accum.
#Readout mode=	Signal
#DeNoise=	Off
#ICS correction=	Off
#Dark correction=	Off
#Inst. Process=	Off
#Detector Gain=	High Sensitivity
#Detector ADC=	45 kHz
#Detector temperature (°C)=	-50.35
#Instrument=	OSD
#Detector=	Syncerity
#Grating=	685
#Laser (nm)=	785
#Spectro (cm-¹)=	2019.74
#Laser power=	60
#E-Cal_Neon=	0
#Full time(s)=	51
#AC=	Not calibrated
#Project=	A
#Sample=	B
#Site=	C
#Title=	SERSxMastCells_1
#Remark=
#Date=	04.10.2024 11:29
#Acquired=	04.10.2024 11:29:49
#AxisType[0]=Intens
#AxisUnit[0]=Cnt
#AxisType[1]=Spectr
#AxisUnit[1]=1/cm
3513.15	331.5
3510.6	317.5
3508.05	302
3505.49	302.5
3502.94	270
3500.38	265.5
3497.82	265
3495.26	257
3492.7	246.5
3490.14	243.5
3487.57	236
3485.01	239
3482.44	239
3479.87	241
3477.3	244
3474.73	257.5
3472.16	255
3469.58	257
3467.01	272
3464.43	262
3461.85	272
3459.28	282
3456.69	292
3454.11	287.5
3451.53	289.5
3448.95	285
3446.36	277
3443.77	274
3441.18	260
3438.59	246.5
3436	227.5
3433.41	218.5
3430.81	202
3428.22	202.5
3425.62	192
3423.02	184
3420.42	191.5
3417.82	182.5
3415.22	197
3412.62	198
3410.01	211
3407.41	213
3404.8	214
3402.19	216
3399.58	216
3396.97	230.5
3394.35	230
3391.74	245
3389.12	232
3386.51	227.5
3383.89	230
3381.27	217
3378.65	212.5
3376.02	197.5
3373.4	207
3370.77	187.5
3368.15	178
3365.52	167
3362.89	167.5
3360.26	160
3357.63	152.5
3354.99	158.5
3352.36	159
3349.72	147.5
3347.08	172.5
3344.44	171.5
3341.8	173.5
3339.16	177
3336.52	187
3333.87	192
3331.23	192.5
3328.58	182.5
3325.93	189.5
3323.28	185
3320.63	187
3317.98	171.5
3315.32	170
3312.66	161.5
3310.01	147
3307.35	139
3304.69	147.5
3302.03	140
3299.36	125.5
3296.7	123.5
3294.04	126
3291.37	127
3288.7	128
3286.03	127
3283.36	129.5
3280.69	129
3278.01	130.5
3275.34	144
3272.66	144
3269.98	152.5
3267.3	149
3264.62	167
3261.94	155
3259.26	162
3256.57	152
3253.89	151.5
3251.2	149.5
3248.51	136
3245.82	136
3243.13	133
3240.43	114.5
3237.74	122.5
3235.04	104
3232.34	112.5
3229.65	101.5
3226.94	110.5
3224.24	106
3221.54	111
3218.84	111
3216.13	114
3213.42	119
3210.71	129.5
3208	138
3205.29	137.5
3202.58	130.5
3199.86	137
3197.15	137.5
3194.43	135.5
3191.71	131.5
3188.99	122
3186.27	123
3183.55	113
3180.82	116
3178.1	107
3175.37	103.5
3172.64	102
3169.91	107
3167.18	107.5
3164.45	102.5
3161.71	104
3158.98	110
3156.24	103.5
3153.5	104
3150.76	114.5
3148.02	113
3145.28	121.5
3142.54	128.5
3139.79	124.5
3137.04	129
3134.29	136.5
3131.54	134
3128.79	130.5
3126.04	133
3123.29	129.5
3120.53	126
3117.77	127
3115.02	118
3112.26	123.5
3109.49	126.5
3106.73	122
3103.97	123.5
3101.2	121
3098.44	128
3095.67	131.5
3092.9	133.5
3090.13	142
3087.35	137
3084.58	156.5
3081.8	157.5
3079.03	160
3076.25	171
3073.47	167
3070.69	172
3067.91	171
3065.12	174.5
3062.34	177.5
3059.55	177.5
3056.76	189.5
3053.97	190.5
3051.18	187
3048.39	195.5
3045.59	201
3042.8	211
3040	224
3037.2	211.5
3034.4	238
3031.6	259
3028.8	271
3025.99	283
3023.19	308
3020.38	339
3017.57	349
3014.76	381
3011.95	408
3009.14	430
3006.32	452.5
3003.51	458.5
3000.69	471
2997.87	465.5
2995.05	441.5
2992.23	436
2989.41	417.5
2986.58	412
2983.76	413.5
2980.93	418
2978.1	426.5
2975.27	433.5
2972.44	467
2969.61	534
2966.77	593.5
2963.94	723
2961.1	893.5
2958.26	1135.5
2955.42	1436
2952.58	1791.5
2949.73	2207.5
2946.89	2523
2944.04	2739
2941.19	2747.5
2938.34	2522
2935.49	2189
2932.64	1736
2929.79	1341
2926.93	1050
2924.08	851
2921.22	665
2918.36	579
2915.5	512
2912.64	441.5
2909.77	391
2906.91	364.5
2904.04	346
2901.17	297
2898.3	307
2895.43	285
2892.56	298.5
2889.68	284.5
2886.81	279.5
2883.93	283.5
2881.05	279.5
2878.17	273.5
2875.29	267.5
2872.41	264.5
2869.52	243.5
2866.64	236
2863.75	232
2860.86	215
2857.97	210
2855.08	203.5
2852.19	212.5
2849.29	210
2846.39	204
2843.5	179
2840.6	182
2837.7	172.5
2834.79	162
2831.89	149.5
2828.99	146
2826.08	128
2823.17	121.5
2820.26	121.5
2817.35	124
2814.44	111.5
2811.52	105
2808.61	108
2805.69	106.5
2802.77	107.5
2799.85	100.5
2796.93	101
2794.01	101
2791.08	96.5
2788.16	103
2785.23	95
2782.3	101
2779.37	103
2776.44	106
2773.5	104
2770.57	109.5
2767.63	107
2764.69	112
2761.75	114
2758.81	115.5
2755.87	129
2752.93	134
2749.98	145.5
2747.03	160.5
2744.09	186
2741.14	197
2738.18	207.5
2735.23	212.5
2732.28	230
2729.32	213
2726.36	179
2723.4	172.5
2720.44	144
2717.48	126
2714.52	120.5
2711.55	113
2708.59	105
2705.62	108.5
2702.65	104.5
2699.68	106
2696.7	102.5
2693.73	91
2690.76	99
2687.78	92.5
2684.8	100.5
2681.82	94.5
2678.84	95.5
2675.85	93
2672.87	93.5
2669.88	94.5
2666.9	92.5
2663.91	93
2660.92	99.5
2657.92	94.5
2654.93	103
2651.93	97
2648.94	97
2645.94	97
2642.94	93
2639.94	96
2636.93	101.5
2633.93	96.5
2630.92	101.5
2627.92	103.5
2624.91	100.5
2621.9	105
2618.88	108.5
2615.87	101.5
2612.86	100
2609.84	102.5
2606.82	107.5
2603.8	109.5
2600.78	96.5
2597.76	103.5
2594.73	105
2591.71	109
2588.68	112
2585.65	101
2582.62	108.5
2579.59	106.5
2576.55	105
2573.52	111.5
2570.48	105.5
2567.44	116.5
2564.4	114
2561.36	117.5
2558.32	116.5
2555.27	117
2552.23	111.5
2549.18	112.5
2546.13	117.5
2543.08	119
2540.03	120.5
2536.98	113.5
2533.92	116
2530.86	120
2527.81	128.5
2524.75	115
2521.68	123.5
2518.62	122
2515.56	124.5
2512.49	131.5
2509.42	127.5
2506.35	131
2503.28	124.5
2500.21	141.5
2497.14	132.5
2494.06	133.5
2490.99	135
2487.91	140.5
2484.83	140.5
2481.75	136.5
2478.66	147
2475.58	144
2472.49	151
2469.4	145.5
2466.31	145.5
2463.22	134.5
2460.13	146
2457.04	147.5
2453.94	147.5
2450.84	146
2447.74	150
2444.64	149.5
2441.54	148.5
2438.44	152
2435.33	153
2432.23	150
2429.12	153.5
2426.01	152
2422.9	167
2419.79	159.5
2416.67	163
2413.56	166.5
2410.44	157.5
2407.32	167.5
2404.2	163.5
2401.08	161
2397.95	155.5
2394.83	162.5
2391.7	154
2388.57	156
2385.44	157
2382.31	166
2379.18	166
2376.04	163
2372.9	161
2369.77	155
2366.63	157
2363.48	166.5
2360.34	170.5
2357.2	167.5
2354.05	182
2350.9	175.5
2347.75	188.5
2344.6	184.5
2341.45	195
2338.3	207.5
2335.14	223.5
2331.98	270
2328.83	303
2325.67	277
2322.5	241
2319.34	244.5
2316.18	264.5
2313.01	270
2309.84	303
2306.67	339.5
2303.5	413
2300.33	556
2297.15	711
2293.98	858.5
2290.8	862
2287.62	729
2284.44	615.5
2281.25	564.5
2278.07	595.5
2274.88	616
2271.7	681.5
2268.51	816
2265.32	1062
2262.12	1557.5
2258.93	2676.5
2255.74	5504.5
2252.54	7496.5
2249.34	5735.5
2246.14	3601
2242.94	2171.5
2239.73	1347
2236.53	928
2233.32	668
2230.11	545
2226.9	467
2223.69	402
2220.48	365
2217.26	324.5
2214.05	309
2210.83	307
2207.61	318
2204.39	347.5
2201.17	302.5
2197.94	286
2194.72	259
2191.49	250
2188.26	235
2185.03	224
2181.8	227
2178.56	227.5
2175.33	212
2172.09	206
2168.85	203.5
2165.61	204
2162.37	200.5
2159.12	196.5
2155.88	200.5
2152.63	215
2149.38	196
2146.13	204.5
2142.88	203
2139.62	211
2136.37	201
2133.11	208
2129.85	203
2126.59	206
2123.33	200.5
2120.07	207
2116.8	205
2113.54	202.5
2110.27	206
2107	203
2103.73	215
2100.45	209
2097.18	203
2093.9	207
2090.62	215
2087.34	216
2084.06	210
2080.78	219.5
2077.49	222.5
2074.21	220
2070.92	208.5
2067.63	213
2064.34	219
2061.04	203
2057.75	222.5
2054.45	213
2051.16	221
2047.86	219
2044.55	221.5
2041.25	227.5
2037.95	227
2034.64	230.5
2031.33	215
2028.02	233
2024.71	234
2021.4	229.5
2018.08	217
2014.77	220
2011.45	224
2008.13	232
2004.81	227.5
2001.49	231
1998.16	227.5
1994.84	245
1991.51	230
1988.18	232
1984.85	236
1981.51	233
1978.18	246
1974.84	248.5
1971.51	240
1968.17	240.5
1964.83	232
1961.48	243.5
1958.14	244
1954.79	253
1951.44	247.5
1948.1	257.5
1944.74	251.5
1941.39	254
1938.04	244
1934.68	253
1931.32	258
1927.96	257
1924.6	235
1921.24	257
1917.87	264.5
1914.51	270.5
1911.14	268
1907.77	274.5
1904.4	262.5
1901.03	263
1897.65	269
1894.28	264.5
1890.9	279
1887.52	272
1884.14	281
1880.75	277
1877.37	279
1873.98	273.5
1870.59	274.5
1867.2	282.5
1863.81	289.5
1860.42	273
1857.02	299.5
1853.63	285.5
1850.23	300
1846.83	278
1843.43	293
1840.02	308
1836.62	302
1833.21	324.5
1829.8	304.5
1826.39	326.5
1822.98	323
1819.57	306.5
1816.15	303
1812.74	308.5
1809.32	304.5
1805.9	311.5
1802.48	313.5
1799.05	314
1795.63	313
1792.2	304.5
1788.77	308
1785.34	311.5
1781.91	317
1778.47	318
1775.04	324
1771.6	323.5
1768.16	331.5
1764.72	328
1761.28	325
1757.83	336
1754.39	333
1750.94	330.5
1747.49	326.5
1744.04	331.5
1740.59	334
1737.13	337
1733.68	330.5
1730.22	342.5
1726.76	335
1723.3	354
1719.83	339
1716.37	337
1712.9	344.5
1709.43	343.5
1705.96	339
1702.49	334
1699.02	349.5
1695.54	338
1692.07	344
1688.59	336.5
1685.11	347.5
1681.62	342.5
1678.14	357
1674.65	343.5
1671.17	344.5
1667.68	344
1664.19	347.5
1660.69	341.5
1657.2	351.5
1653.7	359.5
1650.21	354
1646.71	375.5
1643.21	364
1639.7	372.5
1636.2	376
1632.69	378
1629.18	381
1625.67	393.5
1622.16	386
1618.65	404.5
1615.13	415
1611.62	411.5
1608.1	424
1604.58	420.5
1601.05	425.5
1597.53	422
1594.01	428
1590.48	427
1586.95	444
1583.42	439
1579.88	451
1576.35	454
1572.81	447.5
1569.28	474.5
1565.74	463
1562.19	480
1558.65	516.5
1555.11	555
1551.56	542.5
1548.01	531
1544.46	531.5
1540.91	530
1537.36	549.5
1533.8	553
1530.24	566.5
1526.68	561.5
1523.12	584
1519.56	581.5
1516	584
1512.43	603
1508.86	597.5
1505.29	621.5
1501.72	641.5
1498.15	650.5
1494.57	655
1491	661.5
1487.42	691
1483.84	723
1480.25	729
1476.67	752.5
1473.09	775.5
1469.5	831.5
1465.91	878
1462.32	913
1458.72	1000.5
1455.13	1045.5
1451.53	1084
1447.94	1106
1444.34	1112
1440.73	1108
1437.13	1097.5
1433.53	1062.5
1429.92	1047.5
1426.31	1048.5
1422.7	1050
1419.09	1069
1415.47	1068
1411.86	1044
1408.24	1071
1404.62	1070.5
1401	1065.5
1397.38	1036
1393.75	1060
1390.12	1088.5
1386.49	1181.5
1382.87	1351
1379.23	1649
1375.6	2015.5
1371.96	2011
1368.33	1591
1364.69	1240
1361.05	1015.5
1357.4	889.5
1353.76	804.5
1350.11	770
1346.46	738.5
1342.81	688
1339.16	692.5
1335.51	673.5
1331.85	656
1328.19	651.5
1324.53	618.5
1320.87	611
1317.21	603.5
1313.55	583
1309.88	583.5
1306.21	574
1302.54	562.5
1298.87	538
1295.2	550.5
1291.52	539.5
1287.84	525
1284.16	519
1280.48	516
1276.8	509
1273.12	503
1269.43	501
1265.74	500.5
1262.05	488
1258.36	503
1254.67	486
1250.97	485.5
1247.27	488
1243.57	484
1239.87	501
1236.17	492.5
1232.47	480
1228.76	503
1225.05	492
1221.34	486
1217.63	496
1213.91	504
1210.2	492
1206.48	474.5
1202.76	495.5
1199.04	504.5
1195.32	499.5
1191.59	500
1187.87	504.5
1184.14	515
1180.41	501
1176.67	497.5
1172.94	512.5
1169.2	503.5
1165.47	516
1161.73	505
1157.99	515.5
1154.24	522
1150.5	527.5
1146.75	518.5
1143	525.5
1139.25	516
1135.5	534
1131.74	534.5
1127.99	526
1124.23	528.5
1120.47	546
1116.71	538.5
1112.94	546
1109.18	552
1105.41	540
1101.64	549.5
1097.87	556
1094.1	562.5
1090.32	562.5
1086.55	569
1082.77	581
1078.99	573.5
1075.2	570.5
1071.42	589
1067.63	557
1063.85	596.5
1060.06	598
1056.26	596
1052.47	601.5
1048.67	605.5
1044.88	624
1041.08	631.5
1037.28	624
1033.47	641.5
1029.67	607
1025.86	604.5
1022.05	610.5
1018.24	601
1014.43	576.5
1010.62	588
1006.8	585.5
1002.98	577.5
999.164	591
995.342	580
991.518	576
987.693	599.5
983.866	592.5
980.036	610.5
976.205	588
972.372	602.5
968.537	606.5
964.7	637.5
960.862	605.5
957.021	626.5
953.178	627
949.333	654
945.487	673
941.639	693
937.789	745
933.937	839.5
930.083	1125.5
926.227	2045
922.369	4202
918.51	7006.5
914.649	4448
910.785	1636
906.92	1063
903.052	866
899.184	797
895.313	726.5
891.44	683
887.564	672
883.688	666.5
879.809	647
875.928	643
872.046	627
868.161	635.5
864.275	634.5
860.387	637.5
856.497	639.5
852.604	644
848.711	632
844.815	633.5
840.917	609
837.017	637
833.115	637
829.211	652.5
825.306	664.5
821.399	644
817.489	644
813.578	658.5
809.665	636
805.749	643.5
801.833	665.5
797.913	652
793.992	682
790.069	674.5
786.145	689
782.218	667.5
778.289	692.5
774.358	712.5
770.426	722
766.491	749.5
762.555	775.5
758.616	811
754.676	866.5
750.734	948
746.79	953
742.844	904
738.895	843
734.945	804
730.993	771
727.039	756.5
723.083	732.5
719.125	724
715.166	733
711.204	729
707.24	722
703.274	729.5
699.307	726.5
695.337	739
691.366	728.5
687.392	740.5
683.417	750
679.439	761.5
675.46	769
671.479	757.5
667.495	779
663.51	764.5
659.523	761
655.534	770.5
651.543	796.5
647.549	813
643.555	804
639.557	805
635.558	819.5
631.558	844
627.554	845
623.55	859
619.543	860
615.534	861.5
611.523	852
607.51	878
603.495	865
599.479	872
595.46	874
591.439	852
587.417	859
583.392	879
579.365	866
575.337	884.5
571.306	893.5
567.274	893.5
563.238	914.5
559.202	914.5
555.164	946.5
551.123	920
547.08	942.5
543.036	947.5
538.989	959.5
534.941	991
530.891	960
526.838	948
522.784	973
518.727	949.5
514.668	958
510.608	976.5
506.545	1008
502.48	1000.5
498.414	1017.5
494.346	1005.5
490.275	1054.5
486.202	1027
482.128	1059
478.052	1050.5
473.973	1090
469.893	1097.5
465.811	1121
461.725	1130.5
457.639	1145
453.55	1158.5
449.46	1176.5
445.367	1210
441.273	1245.5
437.176	1244
433.077	1308
428.977	1308.5
424.874	1312.5
420.769	1348
416.663	1430.5
412.554	1477
408.443	1554
404.33	1654.5
400.215	1831
396.098	2127.5
391.979	2646
387.859	3619
383.735	5150
379.611	6050.5
375.484	5727
371.354	4640
367.224	3503
363.09	2692.5
358.955	2186
354.818	1939
350.679	1728.5
346.538	1618.5
342.395	1531.5
338.25	1483
334.102	1413.5
329.953	1430
325.801	1384.5
321.647	1392
317.492	1374.5
313.335	1339.5
309.174	1335
305.014	1319
300.85	1322.5
296.684	1332.5
292.516	1306
288.347	1341.5
284.174	1335
280.001	1353.5
275.824	1337
271.646	1349
267.466	1395
263.283	1373
259.099	1401
254.913	1391.5
250.725	1462
246.535	1474.5
242.342	1489
238.148	1482
233.951	1539.5
229.753	1562.5
225.552	1609
221.349	1635
217.143	1692
212.937	1736
208.727	1806.5
204.516	1890
200.303	1908
196.088	2058.5
191.871	2115
187.651	2224.5
183.43	2345.5
179.206	2459.5
174.981	2637.5
170.753	2770
166.523	2942
162.291	3242
158.057	3512
153.821	3766
149.583	4036.5
145.343	4342
141.101	4666.5
136.856	4943.5
132.61	5222.5
128.361	5482
124.111	5574
119.858	5487
115.603	5071.5
111.346	4335
107.087	3445
102.826	2608.5
98.563	2060.5
94.2969	1654
90.0299	1457.5
87.8957	1349