File: data/Horiba_MacroRAM/CC-124-TAP-2.txt
#Acq. time (s)=	10
#Accumulations=	5
#AutoExposure=	Off
#Spike filter=	Multiple accum.
#Readout mode=	Signal
#DeNoise=	Off
#ICS correction=	Off
#Dark correction=	Off
#Inst. Process=	Off
#Detector Gain=	High Sensitivity
#Detector ADC=	45 kHz
#Detector temperature (°C)=	-49.97
#Instrument=	OSD
#Detector=	Syncerity
#Grating=	685
#Laser (nm)=	785
#Spectro (cm-¹)=	2019.74
#Laser power=	50
#E-Cal_Neon=	0
#Full time(s)=	51
#AC=	Not calibrated
#Project=	A
#Sample=	B
#Site=	C
#Title=	CC-124-TAP-1_4
#Remark=
#Date=	08.10.2024 13:47
#Acquired=	08.10.2024 13:47:42
#AxisType[0]=Intens
#AxisUnit[0]=Cnt
#AxisType[1]=Spectr
#AxisUnit[1]=1/cm
3513.15	22
3510.6	20
3508.05	21
3505.49	22.5
3502.94	23
3500.38	22
3497.82	22
3495.26	23.5
3492.7	29
3490.14	30
3487.57	28.5
3485.01	21.5
3482.44	30.5
3479.87	24
3477.3	26.5
3474.73	25
3472.16	25
3469.58	26.5
3467.01	31.5
3464.43	28
3461.85	27.5
3459.28	31
3456.69	32.5
3454.11	27
3451.53	31.5
3448.95	28
3446.36	29.5
3443.77	29
3441.18	30
3438.59	38
3436	33.5
3433.41	37
3430.81	38
3428.22	31
3425.62	34.5
3423.02	37
3420.42	34
3417.82	32
3415.22	34.5
3412.62	39.5
3410.01	34
3407.41	38
3404.8	37.5
3402.19	38.5
3399.58	37.5
3396.97	40
3394.35	37.5
3391.74	34
3389.12	39
3386.51	41
3383.89	44
3381.27	43
3378.65	39
3376.02	40
3373.4	41
3370.77	40
3368.15	47
3365.52	45.5
3362.89	45
3360.26	47
3357.63	46
3354.99	47
3352.36	49
3349.72	44.5
3347.08	45
3344.44	47
3341.8	50
3339.16	43.5
3336.52	46.5
3333.87	44
3331.23	51.5
3328.58	50
3325.93	51
3323.28	54
3320.63	48
3317.98	51.5
3315.32	49
3312.66	51.5
3310.01	51.5
3307.35	53
3304.69	51
3302.03	56
3299.36	56
3296.7	63
3294.04	54
3291.37	56.5
3288.7	57
3286.03	58.5
3283.36	52
3280.69	60
3278.01	58
3275.34	59
3272.66	61
3269.98	59.5
3267.3	55
3264.62	66
3261.94	63
3259.26	71
3256.57	64.5
3253.89	63
3251.2	60.5
3248.51	70
3245.82	73.5
3243.13	65.5
3240.43	64
3237.74	62
3235.04	70.5
3232.34	71.5
3229.65	71.5
3226.94	68
3224.24	67
3221.54	74
3218.84	68.5
3216.13	70
3213.42	77.5
3210.71	69
3208	72.5
3205.29	76
3202.58	73
3199.86	77.5
3197.15	73
3194.43	75.5
3191.71	76.5
3188.99	75
3186.27	76.5
3183.55	82
3180.82	82.5
3178.1	78
3175.37	81.5
3172.64	71.5
3169.91	77
3167.18	84
3164.45	86
3161.71	90
3158.98	86
3156.24	86
3153.5	87
3150.76	89
3148.02	84.5
3145.28	89.5
3142.54	92
3139.79	92.5
3137.04	89
3134.29	92
3131.54	97
3128.79	97.5
3126.04	93
3123.29	92
3120.53	96
3117.77	101
3115.02	102.5
3112.26	91.5
3109.49	97
3106.73	98
3103.97	101
3101.2	97.5
3098.44	98
3095.67	116
3092.9	110.5
3090.13	102
3087.35	99.5
3084.58	105
3081.8	104
3079.03	112
3076.25	113
3073.47	111
3070.69	113
3067.91	119
3065.12	116.5
3062.34	118.5
3059.55	125
3056.76	123
3053.97	119
3051.18	125
3048.39	133
3045.59	124
3042.8	122
3040	127.5
3037.2	126
3034.4	135.5
3031.6	129
3028.8	135
3025.99	135.5
3023.19	134.5
3020.38	130
3017.57	138
3014.76	130.5
3011.95	134.5
3009.14	140.5
3006.32	135
3003.51	128.5
3000.69	152
2997.87	144
2995.05	146
2992.23	152
2989.41	153
2986.58	151
2983.76	156
2980.93	161
2978.1	166
2975.27	159.5
2972.44	164
2969.61	165
2966.77	164
2963.94	168.5
2961.1	159
2958.26	167
2955.42	171
2952.58	175.5
2949.73	175.5
2946.89	175
2944.04	184
2941.19	176
2938.34	182
2935.49	182
2932.64	178
2929.79	185
2926.93	199
2924.08	191.5
2921.22	193
2918.36	192
2915.5	197
2912.64	201.5
2909.77	201
2906.91	204.5
2904.04	205.5
2901.17	207.5
2898.3	202.5
2895.43	199.5
2892.56	203
2889.68	213
2886.81	205
2883.93	215
2881.05	223
2878.17	222
2875.29	220.5
2872.41	217
2869.52	229
2866.64	232.5
2863.75	227.5
2860.86	219.5
2857.97	231
2855.08	230
2852.19	234
2849.29	224
2846.39	226
2843.5	241
2840.6	247.5
2837.7	238
2834.79	249.5
2831.89	241.5
2828.99	240
2826.08	251
2823.17	252.5
2820.26	261
2817.35	253
2814.44	246
2811.52	263
2808.61	253
2805.69	257.5
2802.77	241
2799.85	267
2796.93	265
2794.01	264
2791.08	270.5
2788.16	260
2785.23	273.5
2782.3	281
2779.37	273
2776.44	281
2773.5	290.5
2770.57	285
2767.63	293
2764.69	298
2761.75	288
2758.81	302
2755.87	295.5
2752.93	296
2749.98	304
2747.03	313.5
2744.09	306
2741.14	317
2738.18	317
2735.23	312.5
2732.28	320
2729.32	322.5
2726.36	326
2723.4	325
2720.44	325.5
2717.48	332
2714.52	331.5
2711.55	323.5
2708.59	327.5
2705.62	331
2702.65	352.5
2699.68	357.5
2696.7	354
2693.73	352
2690.76	356.5
2687.78	358.5
2684.8	349
2681.82	350.5
2678.84	365
2675.85	373.5
2672.87	379.5
2669.88	373
2666.9	366.5
2663.91	383
2660.92	375.5
2657.92	387
2654.93	385.5
2651.93	379
2648.94	384.5
2645.94	388.5
2642.94	384.5
2639.94	391
2636.93	380
2633.93	400
2630.92	406
2627.92	406
2624.91	405
2621.9	428
2618.88	403.5
2615.87	419
2612.86	423.5
2609.84	399
2606.82	428
2603.8	428
2600.78	415
2597.76	405.5
2594.73	415
2591.71	430.5
2588.68	438.5
2585.65	432
2582.62	453.5
2579.59	462
2576.55	448
2573.52	450
2570.48	449
2567.44	462
2564.4	447
2561.36	465
2558.32	465.5
2555.27	473
2552.23	477
2549.18	463.5
2546.13	472.5
2543.08	490
2540.03	492
2536.98	487.5
2533.92	478
2530.86	489
2527.81	495.5
2524.75	504
2521.68	499
2518.62	514
2515.56	503
2512.49	527
2509.42	515.5
2506.35	513
2503.28	524
2500.21	539.5
2497.14	516.5
2494.06	543
2490.99	540.5
2487.91	535
2484.83	542
2481.75	548
2478.66	539.5
2475.58	543.5
2472.49	557
2469.4	566
2466.31	571.5
2463.22	573.5
2460.13	577
2457.04	571
2453.94	590
2450.84	569
2447.74	576
2444.64	586
2441.54	585.5
2438.44	594.5
2435.33	589.5
2432.23	601
2429.12	598
2426.01	596
2422.9	581
2419.79	603.5
2416.67	611.5
2413.56	622
2410.44	616.5
2407.32	633
2404.2	625.5
2401.08	635
2397.95	647
2394.83	633.5
2391.7	651.5
2388.57	635
2385.44	655.5
2382.31	657.5
2379.18	679
2376.04	660
2372.9	657
2369.77	663.5
2366.63	666.5
2363.48	679.5
2360.34	667.5
2357.2	688.5
2354.05	669
2350.9	700.5
2347.75	714.5
2344.6	682
2341.45	697.5
2338.3	698.5
2335.14	713
2331.98	735
2328.83	769.5
2325.67	724
2322.5	735
2319.34	722
2316.18	737.5
2313.01	714.5
2309.84	740
2306.67	732
2303.5	755
2300.33	761
2297.15	743
2293.98	766.5
2290.8	773.5
2287.62	755.5
2284.44	769
2281.25	766.5
2278.07	775.5
2274.88	783.5
2271.7	778.5
2268.51	789
2265.32	806
2262.12	823.5
2258.93	802
2255.74	815.5
2252.54	806
2249.34	827
2246.14	827.5
2242.94	829.5
2239.73	825
2236.53	820.5
2233.32	822.5
2230.11	841
2226.9	844.5
2223.69	845.5
2220.48	853
2217.26	857
2214.05	864.5
2210.83	878
2207.61	899
2204.39	879
2201.17	877
2197.94	880.5
2194.72	897
2191.49	900.5
2188.26	904.5
2185.03	891.5
2181.8	913.5
2178.56	904
2175.33	929
2172.09	912.5
2168.85	925
2165.61	907.5
2162.37	949
2159.12	955.5
2155.88	944.5
2152.63	946.5
2149.38	955
2146.13	963
2142.88	936
2139.62	985.5
2136.37	991.5
2133.11	995
2129.85	978
2126.59	988.5
2123.33	1004
2120.07	1000
2116.8	1017.5
2113.54	1005
2110.27	1001
2107	1010.5
2103.73	1015
2100.45	1001
2097.18	1041.5
2093.9	1014.5
2090.62	1050.5
2087.34	1028.5
2084.06	1025
2080.78	1037
2077.49	1067
2074.21	1056.5
2070.92	1065.5
2067.63	1084
2064.34	1084
2061.04	1074
2057.75	1089.5
2054.45	1100
2051.16	1094.5
2047.86	1116
2044.55	1116
2041.25	1113.5
2037.95	1144
2034.64	1151.5
2031.33	1130
2028.02	1143.5
2024.71	1148
2021.4	1150.5
2018.08	1180.5
2014.77	1158
2011.45	1174.5
2008.13	1185.5
2004.81	1177
2001.49	1200
1998.16	1189.5
1994.84	1207
1991.51	1218
1988.18	1211.5
1984.85	1222
1981.51	1225.5
1978.18	1223.5
1974.84	1211
1971.51	1238
1968.17	1250
1964.83	1270.5
1961.48	1242.5
1958.14	1261.5
1954.79	1259
1951.44	1258
1948.1	1267.5
1944.74	1293.5
1941.39	1273.5
1938.04	1314
1934.68	1308.5
1931.32	1297
1927.96	1301
1924.6	1304
1921.24	1325.5
1917.87	1321.5
1914.51	1341.5
1911.14	1323.5
1907.77	1338.5
1904.4	1342
1901.03	1325.5
1897.65	1339.5
1894.28	1361.5
1890.9	1365.5
1887.52	1376
1884.14	1362.5
1880.75	1352.5
1877.37	1376.5
1873.98	1387
1870.59	1387
1867.2	1402
1863.81	1420.5
1860.42	1421.5
1857.02	1440.5
1853.63	1453
1850.23	1467
1846.83	1454
1843.43	1472.5
1840.02	1445.5
1836.62	1485.5
1833.21	1474
1829.8	1497
1826.39	1492.5
1822.98	1502
1819.57	1503
1816.15	1521.5
1812.74	1516.5
1809.32	1514.5
1805.9	1538
1802.48	1561.5
1799.05	1570
1795.63	1554
1792.2	1581.5
1788.77	1565.5
1785.34	1578
1781.91	1601
1778.47	1590.5
1775.04	1613.5
1771.6	1609
1768.16	1652
1764.72	1659.5
1761.28	1650
1757.83	1631
1754.39	1692
1750.94	1650.5
1747.49	1682
1744.04	1682
1740.59	1682
1737.13	1688
1733.68	1719
1730.22	1696
1726.76	1703
1723.3	1706
1719.83	1704.5
1716.37	1689.5
1712.9	1718
1709.43	1697.5
1705.96	1699
1702.49	1723
1699.02	1733.5
1695.54	1736
1692.07	1729.5
1688.59	1771.5
1685.11	1736.5
1681.62	1779.5
1678.14	1765.5
1674.65	1790
1671.17	1789.5
1667.68	1787
1664.19	1802
1660.69	1776.5
1657.2	1799.5
1653.7	1833.5
1650.21	1823
1646.71	1843
1643.21	1831.5
1639.7	1835.5
1636.2	1863
1632.69	1847.5
1629.18	1887.5
1625.67	1887.5
1622.16	1908
1618.65	1947.5
1615.13	1923.5
1611.62	1998
1608.1	2013
1604.58	2010.5
1601.05	2007
1597.53	2009.5
1594.01	1999.5
1590.48	1986.5
1586.95	2010
1583.42	2011.5
1579.88	2025.5
1576.35	2044
1572.81	2037
1569.28	2072.5
1565.74	2091.5
1562.19	2097.5
1558.65	2118
1555.11	2157.5
1551.56	2190.5
1548.01	2165
1544.46	2163.5
1540.91	2229
1537.36	2272.5
1533.8	2359
1530.24	2470
1526.68	2529.5
1523.12	2537.5
1519.56	2435.5
1516	2360
1512.43	2262.5
1508.86	2222
1505.29	2165.5
1501.72	2181
1498.15	2166
1494.57	2201.5
1491	2230.5
1487.42	2217
1483.84	2252.5
1480.25	2253.5
1476.67	2243.5
1473.09	2241
1469.5	2285.5
1465.91	2269
1462.32	2297.5
1458.72	2289.5
1455.13	2302.5
1451.53	2338.5
1447.94	2345
1444.34	2364.5
1440.73	2417
1437.13	2401
1433.53	2395
1429.92	2343
1426.31	2362
1422.7	2316
1419.09	2376.5
1415.47	2340
1411.86	2379
1408.24	2395.5
1404.62	2402.5
1401	2451
1397.38	2417
1393.75	2452.5
1390.12	2492
1386.49	2468
1382.87	2434.5
1379.23	2455.5
1375.6	2433.5
1371.96	2459
1368.33	2445
1364.69	2463
1361.05	2450
1357.4	2476
1353.76	2512.5
1350.11	2540.5
1346.46	2578.5
1342.81	2555.5
1339.16	2606.5
1335.51	2641.5
1331.85	2723.5
1328.19	2754
1324.53	2832.5
1320.87	2744.5
1317.21	2697
1313.55	2726.5
1309.88	2736
1306.21	2704
1302.54	2713.5
1298.87	2724
1295.2	2712
1291.52	2718.5
1287.84	2796.5
1284.16	2820
1280.48	2783.5
1276.8	2745
1273.12	2735
1269.43	2754.5
1265.74	2773.5
1262.05	2778.5
1258.36	2773.5
1254.67	2773.5
1250.97	2760.5
1247.27	2781.5
1243.57	2808.5
1239.87	2841
1236.17	2836
1232.47	2876
1228.76	2955
1225.05	2940.5
1221.34	2986
1217.63	2956
1213.91	2997.5
1210.2	3005
1206.48	2975.5
1202.76	2970.5
1199.04	3044.5
1195.32	2996
1191.59	3036
1187.87	3077.5
1184.14	3149
1180.41	3130.5
1176.67	3125
1172.94	3094
1169.2	3071.5
1165.47	3110.5
1161.73	3200.5
1157.99	3299
1154.24	3370
1150.5	3294.5
1146.75	3251
1143	3280
1139.25	3211.5
1135.5	3144.5
1131.74	3161.5
1127.99	3139.5
1124.23	3140
1120.47	3134.5
1116.71	3213
1112.94	3246.5
1109.18	3205.5
1105.41	3238.5
1101.64	3221
1097.87	3205.5
1094.1	3204
1090.32	3280.5
1086.55	3274.5
1082.77	3276
1078.99	3284
1075.2	3281.5
1071.42	3327
1067.63	3360
1063.85	3355
1060.06	3356.5
1056.26	3295
1052.47	3351.5
1048.67	3367.5
1044.88	3368.5
1041.08	3329
1037.28	3372
1033.47	3404.5
1029.67	3381.5
1025.86	3390.5
1022.05	3440
1018.24	3417
1014.43	3432
1010.62	3473.5
1006.8	3533
1002.98	3556.5
999.164	3567.5
995.342	3593
991.518	3588.5
987.693	3628.5
983.866	3631
980.036	3628.5
976.205	3609.5
972.372	3658.5
968.537	3635.5
964.7	3650.5
960.862	3645
957.021	3670
953.178	3651.5
949.333	3665
945.487	3691
941.639	3663
937.789	3683.5
933.937	3737.5
930.083	3701
926.227	3772.5
922.369	3821.5
918.51	3820.5
914.649	3820
910.785	3823.5
906.92	3809
903.052	3800.5
899.184	3793.5
895.313	3817
891.44	3780.5
887.564	3808
883.688	3848.5
879.809	3833.5
875.928	3822.5
872.046	3889
868.161	3913.5
864.275	3925.5
860.387	3979.5
856.497	3969.5
852.604	3938
848.711	4026
844.815	4013
840.917	4000
837.017	4029
833.115	4080
829.211	4065
825.306	4084
821.399	4070.5
817.489	4098.5
813.578	4129.5
809.665	4146.5
805.749	4108.5
801.833	4133.5
797.913	4132.5
793.992	4179
790.069	4173
786.145	4211
782.218	4131.5
778.289	4272
774.358	4312.5
770.426	4339.5
766.491	4309.5
762.555	4334.5
758.616	4412.5
754.676	4494
750.734	4455.5
746.79	4565.5
742.844	4595.5
738.895	4546
734.945	4532.5
730.993	4517.5
727.039	4483
723.083	4481
719.125	4505.5
715.166	4521
711.204	4549.5
707.24	4571
703.274	4616
699.307	4609.5
695.337	4607.5
691.366	4606.5
687.392	4663
683.417	4656.5
679.439	4680.5
675.46	4742.5
671.479	4733
667.495	4722
663.51	4783.5
659.523	4749.5
655.534	4843.5
651.543	4840
647.549	4847
643.555	4874
639.557	4880
635.558	4896
631.558	4912
627.554	4914.5
623.55	4925
619.543	5003.5
615.534	4976.5
611.523	5010
607.51	5084
603.495	5078
599.479	5069.5
595.46	5109
591.439	5114
587.417	5189
583.392	5205
579.365	5208
575.337	5228
571.306	5240
567.274	5274.5
563.238	5277.5
559.202	5294
555.164	5305
551.123	5357.5
547.08	5332
543.036	5307
538.989	5299
534.941	5317
530.891	5364
526.838	5329.5
522.784	5353.5
518.727	5330.5
514.668	5367
510.608	5405.5
506.545	5443.5
502.48	5380
498.414	5440
494.346	5554.5
490.275	5486
486.202	5514
482.128	5524
478.052	5628
473.973	5537.5
469.893	5578
465.811	5554
461.725	5578
457.639	5595.5
453.55	5614
449.46	5679
445.367	5707.5
441.273	5679.5
437.176	5706.5
433.077	5778
428.977	5838
424.874	5767.5
420.769	5818
416.663	5838.5
412.554	5789
408.443	5863.5
404.33	5912
400.215	5985
396.098	5956
391.979	5872
387.859	5927.5
383.735	5862.5
379.611	5898
375.484	5888
371.354	6017.5
367.224	5924
363.09	5980.5
358.955	6026
354.818	6010.5
350.679	6030
346.538	6009
342.395	6014
338.25	6061
334.102	6069
329.953	6050
325.801	6120.5
321.647	6039
317.492	6026
313.335	6022
309.174	6026.5
305.014	6039.5
300.85	6088.5
296.684	6034.5
292.516	6013.5
288.347	6135
284.174	6100
280.001	6061.5
275.824	6084
271.646	6099.5
267.466	6128.5
263.283	6091
259.099	6134
254.913	6144.5
250.725	6068.5
246.535	6125.5
242.342	6070.5
238.148	6071.5
233.951	6008.5
229.753	6018
225.552	6007
221.349	5982.5
217.143	6026
212.937	6035.5
208.727	6106.5
204.516	6048
200.303	6092.5
196.088	6054.5
191.871	5999
187.651	5939.5
183.43	5943
179.206	5884
174.981	5885.5
170.753	5851
166.523	5826.5
162.291	5776.5
158.057	5750.5
153.821	5608
149.583	5550.5
145.343	5367
141.101	5171.5
136.856	4969.5
132.61	4722
128.361	4423.5
124.111	4080
119.858	3643.5
115.603	3070
111.346	2478
107.087	1844.5
102.826	1371
98.563	1056
94.2969	829.5
90.0299	751
87.8957	672